<?xml version="1.0" ?>
  <robot name="rover">


  <link name="chassis">
    <visual>
      <geometry>
          <box size=".8 0.7 0.1"/>
      </geometry>
      <material name="gray">
        <color rgba=".2 .2 .2 1" />
      </material>
    </visual>
  <inertial>
            <mass value="2" />
            <inertia ixx="0.04" ixy="0.0" ixz="0" 
            iyy="0.17" iyz="0" izz="0.25" />
    </inertial>
    
    <collision>
      <geometry>
          <box size=".8 0.7 0.1"/>
      </geometry>
    </collision>
  </link>


  <link name="wheel_front_right">
    <inertial>
            <mass value="2" />
            <inertia ixx="1e-3" ixy="0.0" ixz="0" 
            iyy="1e-3" iyz="0" izz="1e-3" />
    </inertial>

    <visual>
      
      <geometry>
          <cylinder radius="0.15" length="0.1"/>
      </geometry>
      <material name="white">
        <color rgba="1 1 1 1"/>
      </material>
    </visual>

    <collision>
    
      <geometry>
          <cylinder radius="0.15" length="0.1"/>
      </geometry>
      <contact_coefficients mu="1" kp="1e+13" kd="1.0"/>
    </collision>
  </link>

  <joint name="wheel_front_right_joint" type="continuous">
    <origin xyz="0 0.4 0.0" rpy="1.57 0.0 0.0"/>
    <parent link="chassis"/>
    <child link="wheel_front_right"/>
    <axis xyz="0.0 0.0 1.0"/>
  </joint>

  <link name="wheel_front_left">
    <inertial>
            <mass value="2" />
            <inertia ixx="1e-3" ixy="0.0" ixz="0" 
            iyy="1e-3" iyz="0" izz="1e-3" />
    </inertial>

    <visual>
      
      <geometry>
          <cylinder radius="0.15" length="0.1"/>
      </geometry>
      <material name="white">
        <color rgba="1 1 1 1"/>
      </material>
    </visual>

    <collision>
      <geometry>
          <cylinder radius="0.15" length="0.1"/>
      </geometry>
      <contact_coefficients mu="1" kp="1e+13" kd="1.0"/>
    </collision>
  </link>

  <joint name="wheel_front_left_joint" type="continuous">
    <origin xyz="0 -0.4 0.0" rpy="1.57 0.0 0.0"/>
    <parent link="chassis"/>
    <child link="wheel_front_left"/>
    <axis xyz="0.0 0.0 1.0"/>

  </joint>

<!--
<link name="wheel_back_right">
    <inertial>
            <mass value="2" />
            <inertia ixx="1e-3" ixy="0.0" ixz="0" 
            iyy="1e-3" iyz="0" izz="1e-3" />
    </inertial>

    <visual>
      
      <geometry>
          <cylinder radius="0.15" length="0.1"/>
      </geometry>
      <material name="white">
        <color rgba="1 1 1 1"/>
      </material>
    </visual>

    <collision>
      <geometry>
          <cylinder radius="0.15" length="0.1"/>
      </geometry>
      <contact_coefficients mu="1" kp="1e+13" kd="1.0"/>
    </collision>
  </link>

  <joint name="wheel_back_right_joint" type="continuous">
    <origin xyz="-0.25 0.4 0.0" rpy="1.57 0.0 0.0"/>
    <parent link="chassis"/>
    <child link="wheel_back_right"/>
    <axis xyz="0.0 0.0 1.0"/>

  </joint>

  <link name="wheel_back_left">
    <inertial>
            <mass value="2" />
            <inertia ixx="1e-3" ixy="0.0" ixz="0" 
            iyy="1e-3" iyz="0" izz="1e-3" />
    </inertial>

    <visual>
      
      <geometry>
          <cylinder radius="0.15" length="0.1"/>
      </geometry>
      <material name="white">
        <color rgba="1 1 1 1"/>
      </material>
    </visual>

    <collision>
      <geometry>
          <cylinder radius="0.15" length="0.1"/>
      </geometry>
      <contact_coefficients mu="1" kp="1e+13" kd="1.0"/>
    </collision>
  </link>

  <joint name="wheel_back_left_joint" type="continuous">
    <origin xyz="-0.25 -0.4 0.0" rpy="1.57 0.0 0.0"/>
    <parent link="chassis"/>
    <child link="wheel_back_left"/>
    <axis xyz="0.0 0.0 1.0"/>

  </joint>
  -->

  <link name="front_castor_wheel">
    <inertial>
            <mass value="2" />
            <inertia ixx="1e-3" ixy="0.0" ixz="0" 
            iyy="1e-3" iyz="0" izz="1e-3" />
    </inertial>

    <visual>
      
      <geometry>
          <sphere radius="0.075"/>
      </geometry>
      <material name="white">
        <color rgba="1 1 1 1"/>
      </material>
    </visual>

    <collision>
      <geometry>
          <sphere radius="0.075"/>
      </geometry>
      <contact_coefficients mu="1" kp="1e+13" kd="1.0"/>
    </collision>
  </link>

  <joint name="castor_wheel_joint" type="fixed">
    <origin xyz="-0.3 0 -0.075" rpy="1.57 0.0 0.0"/>
    <parent link="chassis"/>
    <child link="front_castor_wheel"/>
    <axis xyz="0.0 0.0 1.0"/>

  </joint>

  <link name="back_castor_wheel">
    <inertial>
            <mass value="2" />
            <inertia ixx="1e-3" ixy="0.0" ixz="0" 
            iyy="1e-3" iyz="0" izz="1e-3" />
    </inertial>

    <visual>
      
      <geometry>
          <sphere radius="0.075"/>
      </geometry>
      <material name="white">
        <color rgba="1 1 1 1"/>
      </material>
    </visual>

    <collision>
      <geometry>
          <sphere radius="0.075"/>
      </geometry>
      <contact_coefficients mu="1" kp="1e+13" kd="1.0"/>
    </collision>
  </link>

  <joint name="castor_wheel_joint_2" type="fixed">
    <origin xyz="0.3 0 -0.075" rpy="1.57 0.0 0.0"/>
    <parent link="chassis"/>
    <child link="back_castor_wheel"/>
    <axis xyz="0.0 0.0 1.0"/>

  </joint>

  <link name="lidar">
    <inertial>
            <mass value="0.5" />
            <inertia ixx="0.01" ixy="0.0" ixz="0" 
            iyy="0.01" iyz="0" izz="0.01" />
    </inertial>

    <visual>
      <geometry>
        <cylinder radius="0.1" length="0.1"/>
      </geometry>
      <material name="red">
        <color rgba="1 0 0  1"/>
      </material>
    </visual>

    <collision>
      <geometry>
        <cylinder radius="0.1" length="0.1"/>
      </geometry>
    </collision>
  </link>

  <joint name="lidar_joint" type="fixed">
    <origin xyz="0 0 0.25" rpy="0 0.0 1.57"/>
    <parent link="chassis"/>
    <child link="lidar"/>
    <axis xyz="0.0 0.0 1.0"/>
  </joint>  

  <link name="camera_link">
    <inertial>
      <mass value="0.1"/>
      <inertia ixx="1e-6" ixy="0" ixz="0" iyy="1e-6" iyz="0" izz="1e-6"/>
    </inertial>
    <visual>
      <geometry>
        <box size="0.025 0.09 0.025"/>
      </geometry>
      <material name="blue">
        <color rgba="0 0 1 1"/>
      </material>
    </visual>
    <collision>
      <geometry>
        <box size="0.025 0.09 0.025"/>
      </geometry>
    </collision>
  </link>

  <joint name="camera_joint" type="fixed">
    <parent link="chassis"/>
    <child link="camera_link"/>
    <origin xyz="0.2 0 0.2" rpy="0 0 0"/>
  </joint>

  <gazebo reference="camera_link">
    <sensor type="depth" name="realsense_d435">
      <update_rate>30.0</update_rate>
      <camera>
        <horizontal_fov>1.5</horizontal_fov>
        <image>
          <width>640</width>
          <height>480</height>
        </image>
        <clip>
          <near>0.1</near>
          <far>10.0</far>
        </clip>
      </camera>
      <plugin name="camera_plugin" filename="libgazebo_ros_camera.so">
        <ros>
          <namespace>camera</namespace>
        </ros>
        <frame_name>camera_link</frame_name>
      </plugin>
    </sensor>
  </gazebo>

  <link name="imu_link">
    <inertial>
      <mass value="0.01"/>
      <inertia ixx="1e-6" ixy="0" ixz="0" iyy="1e-6" iyz="0" izz="1e-6"/>
    </inertial>
  </link>

  <joint name="imu_joint" type="fixed">
    <parent link="chassis"/>
    <child link="imu_link"/>
    <origin xyz="0 0 0.1" rpy="0 0 0"/>
  </joint>

  <gazebo reference="imu_link">
    <sensor name="imu_sensor" type="imu">
      <plugin name="imu_plugin" filename="libgazebo_ros_imu_sensor.so">
        <ros>
          <namespace>/</namespace>
          <remapping>~/out:=imu/data</remapping>
        </ros>
        <initial_orientation_as_reference>false</initial_orientation_as_reference>
      </plugin>
    </sensor>
  </gazebo>

<!-- DIFFENERNTIAL DRIVEEEEEEEEEEEEE -->

  <gazebo>
<plugin name='diff_drive' filename='libgazebo_ros_diff_drive.so'>
        <left_joint>wheel_front_left_joint</left_joint>
        <right_joint>wheel_front_right_joint</right_joint>
        <wheel_separation>0.8</wheel_separation>
        <wheel_diameter>0.3</wheel_diameter>
        <max_wheel_torque>20</max_wheel_torque>
        <max_wheel_acceleration>1.0</max_wheel_acceleration>
        <publish_odom>true</publish_odom>
        <publish_odom_tf>true</publish_odom_tf>
        <publish_wheel_tf>true</publish_wheel_tf>

        <odometry_frame>base_footprint</odometry_frame>
        <robot_base_frame>chassis</robot_base_frame>

      </plugin>
</gazebo>




<!-- LIDAAAAAAAAAAAAAAAAAAAAAAAAAAR -->
   <gazebo reference="lidar">
    <sensor name="gazebo_lidar" type="ray">
      <visualize>true</visualize>
      <update_rate>12.0</update_rate>
      <plugin filename="libgazebo_ros_ray_sensor.so" name="gazebo_lidar">
      <ros>
        <remapping>~/out:=scan</remapping>
      </ros>
      
      <output_type>sensor_msgs/LaserScan</output_type>
      <frame_name>lidar</frame_name>
      </plugin>
      <ray>
        <scan>
          <horizontal>
            <samples>720</samples>
            <resolution>1</resolution>
            <min_angle>0.00</min_angle>
            <max_angle>6.28</max_angle>
          </horizontal>
        </scan>
        <range>
          <min>0.120</min>
          <max>3.5</max>
          <resolution>0.015</resolution>
        </range>
        <noise>
          <type>gaussian</type>
          <mean>0.0</mean>
          <stddev>0.01</stddev>
        </noise>
      </ray>
    </sensor>
    <material>Gazebo/DarkGrey</material>
  </gazebo> 
<gazebo reference="wheel_front_right">
    <material>Gazebo/Purple</material>
  </gazebo>

  <gazebo reference="wheel_front_left">
    <material>Gazebo/Purple</material>
  </gazebo>
  
  <!--
  <gazebo reference="wheel_back_right">
    <material>Gazebo/Purple</material>
  </gazebo>
  <gazebo reference="wheel_back_left">
    <material>Gazebo/Purple</material>
  </gazebo>
  -->
  <gazebo reference="chassis">
    <material>Gazebo/Black</material>
  </gazebo>
  <gazebo reference="lidar">
    <material>Gazebo/Purple</material>
  </gazebo>

</robot>